<robot name="kuka_robotiq" version="1.6">

  <!-- ========================================================================= -->
  <!-- ================================= Links ================================= -->
  <!-- ========================================================================= -->

  <link name="world" />

  <link name="arm_iiwa_link_0">
    <inertial>
      <origin rpy="0 -0 0" xyz="-0.1 0 0.07" />
      <mass value="5" />
      <inertia ixx="0.05" ixy="0" ixz="0" iyy="0.06" iyz="0" izz="0.03" />
    </inertial>
    <collision name="iiwa_link_0_collision">
      <origin rpy="0 -0 0" xyz="0 0 0" />
      <geometry>
        <mesh filename="iiwa14/link_0.dae" scale="1 1 1">
        </mesh>
      </geometry>
    </collision>
    <visual name="iiwa_link_0_visual">
      <origin rpy="0 -0 0" xyz="0 0 0" />
      <geometry>
        <mesh filename="iiwa14/link_0.dae" scale="1 1 1">
        </mesh>
      </geometry>
    </visual>
  </link>

  <link name="arm_iiwa_link_1">
    <inertial>
      <origin rpy="0 -0 0" xyz="0 -0.03 0.12" />
      <mass value="4" />
      <inertia ixx="0.1" ixy="0" ixz="0" iyy="0.09" iyz="0" izz="0.02" />
    </inertial>
    <collision name="iiwa_link_1_collision">
      <origin rpy="0 -0 0" xyz="0 0 0" />
      <geometry>
        <mesh filename="iiwa14/link_1.dae" scale="1 1 1">
        </mesh>
      </geometry>
    </collision>
    <visual name="iiwa_link_1_visual">
      <origin rpy="0 -0 0" xyz="0 0 0" />
      <geometry>
        <mesh filename="iiwa14/link_1.dae" scale="1 1 1">
        </mesh>
      </geometry>
    </visual>
  </link>

  <link name="arm_iiwa_link_2">
    <inertial>
      <origin rpy="0 -0 0" xyz="0.0003 0.059 0.042" />
      <mass value="4" />
      <inertia ixx="0.05" ixy="0" ixz="0" iyy="0.018" iyz="0" izz="0.044" />
    </inertial>
    <collision name="iiwa_link_2_collision">
      <origin rpy="0 -0 0" xyz="0 0 0" />
      <geometry>
        <mesh filename="iiwa14/link_2.dae" scale="1 1 1">
        </mesh>
      </geometry>
    </collision>
    <visual name="iiwa_link_2_visual">
      <origin rpy="0 -0 0" xyz="0 0 0" />
      <geometry>
        <mesh filename="iiwa14/link_2.dae" scale="1 1 1">
        </mesh>
      </geometry>
    </visual>
  </link>

  <link name="arm_iiwa_link_3">
    <inertial>
      <origin rpy="0 -0 0" xyz="0 0.03 0.13" />
      <mass value="3" />
      <inertia ixx="0.08" ixy="0" ixz="0" iyy="0.075" iyz="0" izz="0.01" />
    </inertial>
    <collision name="iiwa_link_3_collision">
      <origin rpy="0 -0 0" xyz="0 0 0" />
      <geometry>
        <mesh filename="iiwa14/link_3.dae" scale="1 1 1">
        </mesh>
      </geometry>
    </collision>
    <visual name="iiwa_link_3_visual">
      <origin rpy="0 -0 0" xyz="0 0 0" />
      <geometry>
        <mesh filename="iiwa14/link_3.dae" scale="1 1 1">
        </mesh>
      </geometry>
    </visual>
  </link>

  <link name="arm_iiwa_link_4">
    <inertial>
      <origin rpy="0 0 0" xyz="0 0.067 0.034" />
      <mass value="2.7" />
      <inertia ixx="0.03" ixy="0" ixz="0" iyy="0.01" iyz="0" izz="0.029" />
    </inertial>
    <collision name="iiwa_link_4_collision">
      <origin rpy="0 -0 0" xyz="0 0 0" />
      <geometry>
        <mesh filename="iiwa14/link_4.dae" scale="1 1 1">
        </mesh>
      </geometry>
    </collision>
    <visual name="iiwa_link_4_visual">
      <origin rpy="0 -0 0" xyz="0 0 0" />
      <geometry>
        <mesh filename="iiwa14/link_4.dae" scale="1 1 1">
        </mesh>
      </geometry>
    </visual>
  </link>

  <link name="arm_iiwa_link_5">
    <inertial>
      <origin rpy="0 0 0" xyz="0.0001 0.021 0.076" />
      <mass value="1.7" />
      <inertia ixx="0.02" ixy="0" ixz="0" iyy="0.018" iyz="0" izz="0.005" />
    </inertial>
    <collision name="iiwa_link_5_collision">
      <origin rpy="0 0 0" xyz="0 0 0" />
      <geometry>
        <mesh filename="iiwa14/link_5.dae" scale="1 1 1">
        </mesh>
      </geometry>
    </collision>
    <visual name="iiwa_link_5_visual">
      <origin rpy="0 -0 0" xyz="0 0 0" />
      <geometry>
        <mesh filename="iiwa14/link_5.dae" scale="1 1 1">
        </mesh>
      </geometry>
    </visual>
  </link>

  <link name="arm_iiwa_link_6">
    <inertial>
      <origin rpy="0 0 0" xyz="0 0.0006 0.0004" />
      <mass value="1.8" />
      <inertia ixx="0.005" ixy="0" ixz="0" iyy="0.0036" iyz="0" izz="0.0047" />
    </inertial>
    <collision name="iiwa_link_6_collision">
      <origin rpy="0 -0 0" xyz="0 0 0" />
      <geometry>
        <mesh filename="iiwa14/link_6.dae" scale="1 1 1">
        </mesh>
      </geometry>
    </collision>
    <visual name="iiwa_link_6_visual">
      <origin rpy="0 -0 0" xyz="0 0 0" />
      <geometry>
        <mesh filename="iiwa14/link_6.dae" scale="1 1 1">
        </mesh>
      </geometry>
    </visual>
  </link>

  <link name="arm_iiwa_link_7">
    <inertial>
      <origin rpy="0 -0 0" xyz="0 0 0.02" />
      <mass value="0.3" />
      <inertia ixx="0.001" ixy="0" ixz="0" iyy="0.001" iyz="0" izz="0.001" />
    </inertial>
    <collision name="iiwa_link_7_collision">
      <origin rpy="0 -0 0" xyz="0 0 0" />
      <geometry>
        <mesh filename="iiwa14/link_7.dae" scale="1 1 1">
        </mesh>
      </geometry>
    </collision>
    <visual name="iiwa_link_7_visual">
      <origin rpy="0 -0 0" xyz="0 0 0" />
      <geometry>
        <mesh filename="iiwa14/link_7.dae" scale="1 1 1">
        </mesh>
      </geometry>
    </visual>
  </link>

  <link name="toolchanger_base_link">
    <inertial>
      <mass value="0.6" />
      <inertia ixx="0.00530833" ixy="0" ixz="0" iyy="0.00530833" iyz="0" izz="0.0002" />
    </inertial>
    <visual name="visual1">
      <geometry>
        <mesh filename="millibar_toolchanger/millibar_toolchanger.dae">
        </mesh>
      </geometry>
    </visual>
    <collision name="collision1">
      <origin rpy="0 0 0" xyz="0 0 0" />
      <geometry>
        <mesh filename="millibar_toolchanger/millibar_toolchanger.dae">
        </mesh>
      </geometry>
    </collision>
  </link>

  <link name="toolchanger_tool_attach">
    <inertial>
      <mass value="0.4" />
      <inertia ixx="0.006875" ixy="0" ixz="0" iyy="0.006500" iyz="0" izz="0.011090" />
    </inertial>
    <visual name="visual2">
      <geometry>
        <mesh filename="millibar_toolchanger/millibar_toolchanger_ur3510.stl">
        </mesh>
      </geometry>
    </visual>
    <collision name="collision2">
      <geometry>
        <mesh filename="millibar_toolchanger/millibar_toolchanger_ur3510.stl">
        </mesh>
      </geometry>
    </collision>
  </link>

  <link name="force_torqe_sensor_base_link">
    <inertial>
      <mass value="0.1" />
      <inertia ixx="0.00530833" ixy="0" ixz="0" iyy="0.00530833" iyz="0" izz="0.0002" />
    </inertial>
    <visual name="visual1">
      <geometry>
        <mesh filename="axia_assembly/axia_assembly.dae">
        </mesh>
      </geometry>
    </visual>
    <collision name="collision1">
      <origin rpy="0 0 0" xyz="0 0 0" />
      <geometry>
        <mesh filename="axia_assembly/axia_assembly.dae">
        </mesh>
      </geometry>
    </collision>
  </link>

  <link name="force_torqe_sensor_tool_attach">
    <inertial>
      <mass value="0.1" />
      <inertia ixx="0.00530833" ixy="0" ixz="0" iyy="0.00530833" iyz="0" izz="0.0002" />
    </inertial>
    <visual name="visual2">
      <geometry>
        <mesh filename="axia_assembly/axia_assembly_adapter.stl">
        </mesh>
      </geometry>
    </visual>
    <collision name="collision2">
      <geometry>
        <mesh filename="axia_assembly/axia_assembly_adapter.stl">
        </mesh>
      </geometry>
    </collision>
  </link>

  <link name="robotiq_hande_gripper_body">
    <inertial>
      <mass value="1" />
      <inertia ixx="0.1" ixy="0" ixz="0" iyy="0.1" iyz="0" izz="0.1" />
    </inertial>
    <visual name="visual1">
      <geometry>
        <mesh filename="robotiq_hande/robotiq_hande_body_c01.stl">
        </mesh>
      </geometry>
    </visual>
    <visual name="visual2">
      <geometry>
        <mesh filename="robotiq_hande/robotiq_hande_body_c02.stl">
        </mesh>
      </geometry>
    </visual>
    <collision name="collision1">
      <origin rpy="0 0 0" xyz="0 0 0" />
      <geometry>
        <mesh filename="robotiq_hande/robotiq_hande_body_c01.stl">
        </mesh>
      </geometry>
    </collision>
    <collision name="collision2">
      <origin rpy="0 0 0" xyz="0 0 0" />
      <geometry>
        <mesh filename="robotiq_hande/robotiq_hande_body_c02.stl">
        </mesh>
      </geometry>
    </collision>
  </link>

  <link name="robotiq_hande_gripper_finger1">
    <inertial>
      <mass value="0.1" />
      <inertia ixx="0.1" ixy="0" ixz="0" iyy="0.1" iyz="0" izz="0.1" />
    </inertial>
    <visual name="visual1">
      <origin rpy="0 0 0" xyz="0 0 0" />
      <geometry>
        <mesh filename="robotiq_hande/robotiq_hande_finger_c01.stl">
        </mesh>
      </geometry>
    </visual>
    <visual name="visual2">
      <origin rpy="0 0 0" xyz="0 0 0" />
      <geometry>
        <mesh filename="robotiq_hande/robotiq_hande_finger_c02.stl">
        </mesh>
      </geometry>
    </visual>
    <visual name="visual3">
      <origin rpy="0 0 0" xyz="0 0 0" />
      <geometry>
        <mesh filename="robotiq_hande/robotiq_hande_finger_c03.stl">
        </mesh>
      </geometry>
    </visual>
    <visual name="visual4">
      <origin rpy="0 0 0" xyz="0 0 0" />
      <geometry>
        <mesh filename="robotiq_hande/robotiq_hande_finger_c04.stl">
        </mesh>
      </geometry>
    </visual>
    <collision name="collision1">
      <origin rpy="0 0 0" xyz="0 0 0" />
      <geometry>
        <mesh filename="robotiq_hande/robotiq_hande_finger_c01.stl">
        </mesh>
      </geometry>
    </collision>
    <collision name="collision2">
      <origin rpy="0 0 0" xyz="0 0 0" />
      <geometry>
        <mesh filename="robotiq_hande/robotiq_hande_finger_c02.stl">
        </mesh>
      </geometry>
    </collision>
    <collision name="collision3">
      <origin rpy="0 0 0" xyz="0 0 0" />
      <geometry>
        <mesh filename="robotiq_hande/robotiq_hande_finger_c03.stl">
        </mesh>
      </geometry>
    </collision>
    <collision name="collision4">
      <origin rpy="0 0 0" xyz="0 0 0" />
      <geometry>
        <mesh filename="robotiq_hande/robotiq_hande_finger_c04.stl">
        </mesh>
      </geometry>
    </collision>
  </link>

  <link name="robotiq_hande_gripper_finger2">
    <inertial>
      <mass value="0.1" />
      <inertia ixx="0.1" ixy="0" ixz="0" iyy="0.1" iyz="0" izz="0.1" />
    </inertial>
    <visual name="visual1">
      <origin rpy="0 0 3.14157" xyz="0 0 0" />
      <geometry>
        <mesh filename="robotiq_hande/robotiq_hande_finger_c01.stl">
        </mesh>
      </geometry>
    </visual>
    <visual name="visual2">
      <origin rpy="0 0 3.14157" xyz="0 0 0" />
      <geometry>
        <mesh filename="robotiq_hande/robotiq_hande_finger_c02.stl">
        </mesh>
      </geometry>
    </visual>
    <visual name="visual3">
      <origin rpy="0 0 3.14157" xyz="0 0 0" />
      <geometry>
        <mesh filename="robotiq_hande/robotiq_hande_finger_c03.stl">
        </mesh>
      </geometry>
    </visual>
    <visual name="visual4">
      <origin rpy="0 0 3.14157" xyz="0 0 0" />
      <geometry>
        <mesh filename="robotiq_hande/robotiq_hande_finger_c04.stl">
        </mesh>
      </geometry>
    </visual>
    <collision name="collision1">
      <origin rpy="0 0 3.14157" xyz="0 0 0" />
      <geometry>
        <mesh filename="robotiq_hande/robotiq_hande_finger_c01.stl">
        </mesh>
      </geometry>
    </collision>
    <collision name="collision2">
      <origin rpy="0 0 3.14157" xyz="0 0 0" />
      <geometry>
        <mesh filename="robotiq_hande/robotiq_hande_finger_c02.stl">
        </mesh>
      </geometry>
    </collision>
    <collision name="collision3">
      <origin rpy="0 0 3.14157" xyz="0 0 0" />
      <geometry>
        <mesh filename="robotiq_hande/robotiq_hande_finger_c03.stl">
        </mesh>
      </geometry>
    </collision>
    <collision name="collision4">
      <origin rpy="0 0 3.14157" xyz="0 0 0" />
      <geometry>
        <mesh filename="robotiq_hande/robotiq_hande_finger_c04.stl">
        </mesh>
      </geometry>
    </collision>
  </link>

  <!-- ========================================================================== -->
  <!-- ================================= Joints ================================= -->
  <!-- ========================================================================== -->

  <joint name="world_iiwa_joint" type="fixed">
    <child link="arm_iiwa_link_0" />
    <parent link="world" />
  </joint>

  <joint name="iiwa_joint_1" type="revolute">
    <child link="arm_iiwa_link_1" />
    <parent link="arm_iiwa_link_0" />
    <limit effort="320" lower="-2.96" upper="2.96" velocity="10" />
    <dynamics damping="2.0" friction="1.0" spring_reference="0" spring_stiffness="0" />
    <axis xyz="0 0 1" />
    <origin rpy="0.0 0.0 0.0" xyz="0.0 0.0 0.1575" />
  </joint>
  
  <joint name="iiwa_joint_2" type="revolute">
    <child link="arm_iiwa_link_2" />
    <parent link="arm_iiwa_link_1" />
    <limit effort="320" lower="-2.09" upper="2.09" velocity="10" />
    <dynamics damping="2.0" friction="1.0" spring_reference="0" spring_stiffness="0" />
    <axis xyz="0 0 1" />
    <origin rpy="1.5708 -0.0 3.14159" xyz="0.0 0.0 0.20249999999999999" />
  </joint>

  <joint name="iiwa_joint_3" type="revolute">
    <child link="arm_iiwa_link_3" />
    <parent link="arm_iiwa_link_2" />
    <limit effort="176" lower="-2.96" upper="2.96" velocity="10" />
    <dynamics damping="2.0" friction="1.0" spring_reference="0" spring_stiffness="0" />
    <axis xyz="0 0 1" />
    <origin rpy="1.5708 -2.6535897933379425e-06 3.1415926535800462" xyz="9.116907345086933e-29 0.20449999999862045 -7.511704436343742e-07" />
  </joint>

  <joint name="iiwa_joint_4" type="revolute">
    <child link="arm_iiwa_link_4" />
    <parent link="arm_iiwa_link_3" />
    <limit effort="176" lower="-2.09" upper="2.09" velocity="10" />
    <dynamics damping="2.0" friction="1.0" spring_reference="0" spring_stiffness="0" />
    <axis xyz="0 0 1" />
    <origin rpy="1.5708 -0.0 0.0" xyz="0.0 0.0 0.21550000000000002" />
  </joint>

  <joint name="iiwa_joint_5" type="revolute">
    <child link="arm_iiwa_link_5" />
    <parent link="arm_iiwa_link_4" />
    <limit effort="110" lower="-2.96" upper="2.96" velocity="10" />
    <dynamics damping="2.0" friction="1.0" spring_reference="0" spring_stiffness="0" />
    <axis xyz="0 0 1" />
    <origin rpy="1.5708 2.6535897933379425e-06 -3.1415926535800462" xyz="0.0 0.18449999999875533 -6.777063415674434e-07" />
  </joint>

  <joint name="iiwa_joint_6" type="revolute">
    <child link="arm_iiwa_link_6" />
    <parent link="arm_iiwa_link_5" />
    <limit effort="40" lower="-2.09" upper="2.09" velocity="10" />
    <dynamics damping="2.0" friction="1.0" spring_reference="0" spring_stiffness="0" />
    <axis xyz="0 0 1" />
    <origin rpy="1.5708 -0.0 -1.7565425622120319e-22" xyz="0.0 0.0 0.2154999999999999" />
  </joint>

  <joint name="iiwa_joint_7" type="revolute">
    <child link="arm_iiwa_link_7" />
    <parent link="arm_iiwa_link_6" />
    <limit effort="40" lower="-3.0543300000000002" upper="3.0543300000000002" velocity="10" />
    <dynamics damping="2.0" friction="1.0" spring_reference="0" spring_stiffness="0" />
    <axis xyz="0 0 1" />
    <origin rpy="1.5708 -2.6535897933379425e-06 3.1415926535800462" xyz="1.9014789953427065e-27 0.08099999999945351 -2.9752961337107144e-07" />
  </joint>

  <joint name="toolchanger_joint" type="fixed">
    <parent link="arm_iiwa_link_7" />
    <child link="toolchanger_base_link" />
    <origin rpy="0.0 -0.0 -1.5708" xyz="0.0 0.0 0.074261" />
  </joint>

  <joint name="attach_joint" type="fixed">
    <parent link="toolchanger_base_link" />
    <child link="toolchanger_tool_attach" />
    <origin rpy="0.0 -0.0 3.617441230323139e-22" xyz="0.0 0.0 0.0" />
  </joint>

  <joint name="force_torqe_sensor_joint" type="fixed">
    <parent link="toolchanger_tool_attach" />
    <child link="force_torqe_sensor_base_link" />
    <origin rpy="0.0 -0.0 3.617441230323139e-22" xyz="0.0 0.0 0.03695699999999991" />
  </joint>

  <joint name="attach_joint_" type="fixed">
    <parent link="force_torqe_sensor_base_link" />
    <child link="force_torqe_sensor_tool_attach" />
    <origin rpy="0.0 -0.0 3.617441230323139e-22" xyz="0.0 0.0 0.0" />
  </joint>

  <joint name="axia_gripper_joint" type="fixed">
    <parent link="force_torqe_sensor_tool_attach" />
    <child link="robotiq_hande_gripper_body" />
    <origin rpy="0.0 -0.0 -1.5707889803895865" xyz="0.0 0.0 -0.027666999999999914" />
  </joint>

  <joint name="finger1" type="prismatic">
    <parent link="robotiq_hande_gripper_body" />
    <child link="robotiq_hande_gripper_finger1" />
    <limit lower="0" upper="0.025" effort='100'  velocity="10" />
    <axis xyz="0 1 0" />
    <origin rpy="0.0 -0.0 -3.617441230323139e-22" xyz="0.0 0.0 0.0" />
  </joint>

  <joint name="finger2" type="prismatic">
    <parent link="robotiq_hande_gripper_body" />
    <child link="robotiq_hande_gripper_finger2" />
    <limit lower="0" upper="0.025" effort='100'  velocity="10" />
    <axis xyz="0 -1 0" />
    <origin rpy="0.0 -0.0 -3.617441230323139e-22" xyz="0.0 0.0 0.0" />
  </joint>

  <!-- ========================================================================= -->
  <!-- ========================= Virtual Grasp Target ========================== -->
  <!-- ========================================================================= -->

  <link name="grasptarget">
    <inertial>
      <origin rpy="0 0 0" xyz="0 0 0"/>
       <mass value="0.001"/>
       <inertia ixx="0.1" ixy="0" ixz="0" iyy="0.1" iyz="0" izz="0.1"/>
    </inertial>
    <visual>
      <geometry>
        <sphere radius="0.003"/>
      </geometry>
      <color rgba="1. 0. 0. 1.0"/>
    </visual>
  </link>

  <joint name="grasp_target" type="fixed">
    <parent link="robotiq_hande_gripper_body"/>
    <child link="grasptarget"/>
    <origin rpy="0 0 0" xyz="0 0 0.22"/>
  </joint>

</robot>