<robot name="kuka_robotiq" version="1.6">

  <!-- ========================================================================= -->
  <!-- ================================= Links ================================= -->
  <!-- ========================================================================= -->

  <link name="world" />

  <link name="arm_iiwa_link_0">
    <inertial>
      <origin rpy="0 -0 0" xyz="-0.1 0 0.07" />
      <mass value="5" />
      <inertia ixx="1.0" ixy="0" ixz="0" iyy="1.0" iyz="0" izz="1.0" />
    </inertial>
    <collision name="iiwa_link_0_collision">
      <origin rpy="0 -0 0" xyz="0 0 0" />
      <geometry>
        <mesh filename="iiwa14/simple/link_0.stl" scale="1 1 1">
        </mesh>
      </geometry>
    </collision>
    <visual name="iiwa_link_0_visual">
      <origin rpy="0 -0 0" xyz="0 0 0" />
      <geometry>
        <mesh filename="iiwa14/simple/link_0.stl" scale="1 1 1">
        </mesh>
      </geometry>
    </visual>
  </link>

  <link name="arm_iiwa_link_1">
    <inertial>
      <origin rpy="0 -0 0" xyz="0 -0.03 0.12" />
      <mass value="4" />
      <inertia ixx="1.0" ixy="0" ixz="0" iyy="1.0" iyz="0" izz="1.0" />
    </inertial>
    <collision name="iiwa_link_1_collision">
      <origin rpy="0 -0 0" xyz="0 0 0" />
      <geometry>
        <mesh filename="iiwa14/simple/link_1.stl" scale="1 1 1">
        </mesh>
      </geometry>
    </collision>
    <visual name="iiwa_link_1_visual">
      <origin rpy="0 -0 0" xyz="0 0 0" />
      <geometry>
        <mesh filename="iiwa14/simple/link_1.stl" scale="1 1 1">
        </mesh>
      </geometry>
    </visual>
  </link>

  <link name="arm_iiwa_link_2">
    <inertial>
      <origin rpy="0 -0 0" xyz="0.0003 0.059 0.042" />
      <mass value="4" />
      <inertia ixx="1.0" ixy="0" ixz="0" iyy="1.0" iyz="0" izz="1.0" />
    </inertial>
    <collision name="iiwa_link_2_collision">
      <origin rpy="0 -0 0" xyz="0 0 0" />
      <geometry>
        <mesh filename="iiwa14/simple/link_2.stl" scale="1 1 1">
        </mesh>
      </geometry>
    </collision>
    <visual name="iiwa_link_2_visual">
      <origin rpy="0 -0 0" xyz="0 0 0" />
      <geometry>
        <mesh filename="iiwa14/simple/link_2.stl" scale="1 1 1">
        </mesh>
      </geometry>
    </visual>
  </link>

  <link name="arm_iiwa_link_3">
    <inertial>
      <origin rpy="0 -0 0" xyz="0 0.03 0.13" />
      <mass value="3" />
      <inertia ixx="1.0" ixy="0" ixz="0" iyy="1.0" iyz="0" izz="1.0" />
    </inertial>
    <collision name="iiwa_link_3_collision">
      <origin rpy="0 -0 0" xyz="0 0 0" />
      <geometry>
        <mesh filename="iiwa14/simple/link_3.stl" scale="1 1 1">
        </mesh>
      </geometry>
    </collision>
    <visual name="iiwa_link_3_visual">
      <origin rpy="0 -0 0" xyz="0 0 0" />
      <geometry>
        <mesh filename="iiwa14/simple/link_3.stl" scale="1 1 1">
        </mesh>
      </geometry>
    </visual>
  </link>

  <link name="arm_iiwa_link_4">
    <inertial>
      <origin rpy="0 0 0" xyz="0 0.067 0.034" />
      <mass value="2.7" />
      <inertia ixx="1.0" ixy="0" ixz="0" iyy="1.0" iyz="0" izz="1.0" />
    </inertial>
    <collision name="iiwa_link_4_collision">
      <origin rpy="0 -0 0" xyz="0 0 0" />
      <geometry>
        <mesh filename="iiwa14/simple/link_4.stl" scale="1 1 1">
        </mesh>
      </geometry>
    </collision>
    <visual name="iiwa_link_4_visual">
      <origin rpy="0 -0 0" xyz="0 0 0" />
      <geometry>
        <mesh filename="iiwa14/simple/link_4.stl" scale="1 1 1">
        </mesh>
      </geometry>
    </visual>
  </link>

  <link name="arm_iiwa_link_5">
    <inertial>
      <origin rpy="0 0 0" xyz="0.0001 0.021 0.076" />
      <mass value="1.7" />
      <inertia ixx="1.0" ixy="0" ixz="0" iyy="1.0" iyz="0" izz="1.0" />
    </inertial>
    <collision name="iiwa_link_5_collision">
      <origin rpy="0 0 0" xyz="0 0 0" />
      <geometry>
        <mesh filename="iiwa14/simple/link_5.stl" scale="1 1 1">
        </mesh>
      </geometry>
    </collision>
    <visual name="iiwa_link_5_visual">
      <origin rpy="0 -0 0" xyz="0 0 0" />
      <geometry>
        <mesh filename="iiwa14/simple/link_5.stl" scale="1 1 1">
        </mesh>
      </geometry>
    </visual>
  </link>

  <link name="arm_iiwa_link_6">
    <inertial>
      <origin rpy="0 0 0" xyz="0 0.0006 0.0004" />
      <mass value="1.8" />
      <inertia ixx="1.0" ixy="0" ixz="0" iyy="1.0" iyz="0" izz="1.0" />
    </inertial>
    <collision name="iiwa_link_6_collision">
      <origin rpy="0 -0 0" xyz="0 0 0" />
      <geometry>
        <mesh filename="iiwa14/simple/link_6.stl" scale="1 1 1">
        </mesh>
      </geometry>
    </collision>
    <visual name="iiwa_link_6_visual">
      <origin rpy="0 -0 0" xyz="0 0 0" />
      <geometry>
        <mesh filename="iiwa14/simple/link_6.stl" scale="1 1 1">
        </mesh>
      </geometry>
    </visual>
  </link>

  <link name="arm_iiwa_link_7">
    <inertial>
      <origin rpy="0 -0 0" xyz="0 0 0.02" />
      <mass value="2.7" />
      <inertia ixx="1.0" ixy="0" ixz="0" iyy="1.0" iyz="0" izz="1.0" />
    </inertial>
    <collision name="iiwa_link_7_collision">
      <origin rpy="0 -0 0" xyz="0 0 0" />
      <geometry>
        <mesh filename="iiwa14/simple/link_7_combined.stl" scale="1 1 1">
        </mesh>
      </geometry>
    </collision>
    <visual name="iiwa_link_7_visual">
      <origin rpy="0 -0 0" xyz="0 0 0" />
      <geometry>
        <mesh filename="iiwa14/simple/link_7_combined.stl" scale="1 1 1">
        </mesh>
      </geometry>
    </visual>
  </link>

  <link name="camera_mount">
    <inertial>
      <origin rpy="0 -0 0" xyz="0 0 0.02" />
      <mass value="0.01" />
      <inertia ixx="0.01" ixy="0" ixz="0" iyy="0.01" iyz="0" izz="0.01" />
    </inertial>
    <collision name="camera_mount_collision">
      <origin rpy="0 -0 0" xyz="0 0 0" />
      <geometry>
        <mesh filename="iiwa14/simple/link_7_cam_mount.stl" scale="1 1 1">
        </mesh>
      </geometry>
    </collision>
    <visual name="camera_mount_visual">
      <origin rpy="0 -0 0" xyz="0 0 0" />
      <geometry>
        <mesh filename="iiwa14/simple/link_7_cam_mount.stl" scale="1 1 1">
        </mesh>
      </geometry>
    </visual>
  </link>

  <link name="robotiq_hande_gripper_finger1">
    <inertial>
      <mass value="0.05" />
      <inertia ixx="0.00000892" ixy="0" ixz="0" iyy="0.00001048" iyz="0" izz="0.00000177" />
    </inertial>
    <visual name="visual1">
      <origin rpy="0 0 0" xyz="0 0 0" />
      <geometry>
        <mesh filename="robotiq_hande/robotiq_hande_finger.stl">
        </mesh>
      </geometry>
    </visual>
    <collision name="collision1">
      <origin rpy="0 0 0" xyz="0 0 0" />
      <geometry>
        <mesh filename="robotiq_hande/robotiq_hande_finger.stl">
        </mesh>
      </geometry>
    </collision>
  </link>

  <link name="robotiq_hande_gripper_finger2">
    <inertial>
      <mass value="0.05" />
      <inertia ixx="0.00000892" ixy="0" ixz="0" iyy="0.00001048" iyz="0" izz="0.00000177" />
    </inertial>
    <visual name="visual1">
      <origin rpy="0 0 0" xyz="0 0 0" />
      <geometry>
        <mesh filename="robotiq_hande/robotiq_hande_finger.stl">
        </mesh>
      </geometry>
    </visual>
    <collision name="collision1">
      <origin rpy="0 0 0" xyz="0 0 0" />
      <geometry>
        <mesh filename="robotiq_hande/robotiq_hande_finger.stl">
        </mesh>
      </geometry>
    </collision>
  </link>

  <!-- ========================================================================== -->
  <!-- ================================= Joints ================================= -->
  <!-- ========================================================================== -->

  <joint name="world_iiwa_joint" type="fixed">
    <child link="arm_iiwa_link_0" />
    <parent link="world" />
    <origin rpy="0 0 0" xyz="0 0 0.0"/>
  </joint>

  <joint name="iiwa_joint_1" type="revolute">
    <child link="arm_iiwa_link_1" />
    <parent link="arm_iiwa_link_0" />
    <limit effort="320" lower="-2.96" upper="2.96" velocity="10" />
    <dynamics damping="1.5" friction="1.0" spring_reference="0" spring_stiffness="0" />
    <axis xyz="0 0 1" />
    <origin rpy="0.0 0.0 0.0" xyz="0.0 0.0 0.1575" />
  </joint>
  
  <joint name="iiwa_joint_2" type="revolute">
    <child link="arm_iiwa_link_2" />
    <parent link="arm_iiwa_link_1" />
    <limit effort="320" lower="-2.09" upper="2.09" velocity="10" />
    <dynamics damping="1.5" friction="1.0" spring_reference="0" spring_stiffness="0" />
    <axis xyz="0 0 1" />
    <origin rpy="1.5708 -0.0 3.14159" xyz="0.0 0.0 0.20249999999999999" />
  </joint>

  <joint name="iiwa_joint_3" type="revolute">
    <child link="arm_iiwa_link_3" />
    <parent link="arm_iiwa_link_2" />
    <limit effort="176" lower="-2.96" upper="2.96" velocity="10" />
    <dynamics damping="1.5" friction="1.0" spring_reference="0" spring_stiffness="0" />
    <axis xyz="0 0 1" />
    <origin rpy="1.5708 -2.6535897933379425e-06 3.1415926535800462" xyz="9.116907345086933e-29 0.20449999999862045 -7.511704436343742e-07" />
  </joint>

  <joint name="iiwa_joint_4" type="revolute">
    <child link="arm_iiwa_link_4" />
    <parent link="arm_iiwa_link_3" />
    <limit effort="176" lower="-2.09" upper="2.09" velocity="10" />
    <dynamics damping="1.5" friction="1.0" spring_reference="0" spring_stiffness="0" />
    <axis xyz="0 0 1" />
    <origin rpy="1.5708 -0.0 0.0" xyz="0.0 0.0 0.21550000000000002" />
  </joint>

  <joint name="iiwa_joint_5" type="revolute">
    <child link="arm_iiwa_link_5" />
    <parent link="arm_iiwa_link_4" />
    <limit effort="110" lower="-2.96" upper="2.96" velocity="10" />
    <dynamics damping="1.5" friction="1.0" spring_reference="0" spring_stiffness="0" />
    <axis xyz="0 0 1" />
    <origin rpy="1.5708 2.6535897933379425e-06 -3.1415926535800462" xyz="0.0 0.18449999999875533 -6.777063415674434e-07" />
  </joint>

  <joint name="iiwa_joint_6" type="revolute">
    <child link="arm_iiwa_link_6" />
    <parent link="arm_iiwa_link_5" />
    <limit effort="70" lower="-2.09" upper="2.09" velocity="10" />
    <dynamics damping="1.5" friction="1.0" spring_reference="0" spring_stiffness="0" />
    <axis xyz="0 0 1" />
    <origin rpy="1.5708 -0.0 -1.7565425622120319e-22" xyz="0.0 0.0 0.2154999999999999" />
  </joint>

  <joint name="iiwa_joint_7" type="revolute">
    <child link="arm_iiwa_link_7" />
    <parent link="arm_iiwa_link_6" />
    <limit effort="70" lower="-3.0543300000000002" upper="3.0543300000000002" velocity="10" />
    <dynamics damping="1.5" friction="1.0" spring_reference="0" spring_stiffness="0" />
    <axis xyz="0 0 1" />
    <origin rpy="1.5708 -2.6535897933379425e-06 3.1415926535800462" xyz="0 0.08099999999945351 0" />
  </joint>

  <joint name="hande_to_camera_mount" type="fixed">
    <parent link="arm_iiwa_link_7" />
    <child link="camera_mount" />
    <origin rpy="0.0 0.0 -0.7854" xyz="0.0 0.0 0.0" />
  </joint>

  <joint name="hande_to_f1" type="fixed">
    <parent link="arm_iiwa_link_7" />
    <child link="robotiq_hande_gripper_finger1" />
    <origin rpy="0.0 0.0 0" xyz="0.0 0.0 0.2575" />
  </joint>

  <joint name="hande_to_f2" type="fixed">
    <parent link="arm_iiwa_link_7" />
    <child link="robotiq_hande_gripper_finger2" />
    <origin rpy="0.0 0.0 3.14159" xyz="0.0 0.0 0.2575" />
  </joint>

  <!-- ========================================================================= -->
  <!-- ========================= Virtual Grasp Target ========================== -->
  <!-- ========================================================================= -->

  <link name="grasptarget">
    <inertial>
      <origin rpy="0 0 0" xyz="0 0 0"/>
       <mass value="0.0001"/>
       <inertia ixx="0.1" ixy="0" ixz="0" iyy="0.1" iyz="0" izz="0.1"/>
    </inertial>
    <visual>
      <geometry>
        <sphere radius="0.003"/>
      </geometry>
      <color rgba="1. 0. 0. 1.0"/>
    </visual>
  </link>

  <joint name="grasp_target" type="fixed">
    <parent link="arm_iiwa_link_7"/>
    <child link="grasptarget"/>
    <origin rpy="0 0 0" xyz="0 0 0.2975"/>
  </joint>

</robot>